<?xml version="1.0" ?>
<robot name="padbot_p1" xmlns:xacro="http://ros.org/wiki/xacro">
    <material name="white">
        <color rgba="1.0 1.0 1.0 1.0"/>
    </material>
    <material name="grey">
        <color rgba="0.5 0.5 0.5 1.0"/>
    </material>
    <material name="black">
        <color rgba="0.0 0.0 0.0 1.0"/>
    </material>
    
    <link name="base_footprint">
      <visual>
        <origin xyz="0 0 0" rpy="0 0 0" />
        <geometry>
          <box size="0.001 0.001 0.001" />
        </geometry>
        <material name="Green" />
      </visual>

      <collision>
        <origin xyz="0 0 0.017" rpy="0 0 0" />
        <geometry>
          <box size="0.001 0.001 0.001" />
        </geometry>
      </collision>
    </link>
    
    <link name="base_link">
        <inertial>
            <mass value="2"/>
            <origin xyz="0 0 0.0"/>
            <inertia ixx="0.01" ixy="0.0" ixz="0.0" iyy="0.01" iyz="0.0" izz="0.5"/>
        </inertial>
        <visual>
            <origin rpy="0 0 0" xyz="0 0 0"/>
            <geometry>
                <box size="0.35 0.26 0.13"/>
            </geometry>
            <material name="white"/>
        </visual>
        <collision>
            <origin rpy="0 0 0" xyz="0 0 0"/>
            <geometry>
                <box size="0.35 0.26 0.13"/>
            </geometry>
        </collision>
    </link>
    <link name="pole">
        <inertial>
            <mass value="0.001"/>
            <origin xyz="0 0 0"/>
            <inertia ixx="0.0001" ixy="0.0" ixz="0.0" iyy="0.0001" iyz="0.0" izz="0.0001"/>
        </inertial>
        <visual>
            <origin rpy="0 0 0" xyz="0 0 0.415"/>
            <geometry>
                <cylinder length="0.765" radius="0.03"/>
            </geometry>
            <material name="white"/>
        </visual>
        <collision>
            <origin rpy="0 0 0" xyz="0 0 0.34"/>
            <geometry>
                <cylinder length="0.765" radius="0.03"/>
            </geometry>
        </collision>
    </link>
    <link name="tablet_holder">
        <inertial>
            <mass value="0.001"/>
            <origin xyz="0 0 0"/>
            <inertia ixx="0.0001" ixy="0.0" ixz="0.0" iyy="0.0001" iyz="0.0" izz="0.0001"/>
        </inertial>
        <visual>
            <origin rpy="0 0 0" xyz="0 0 0"/>
            <geometry>
                <box size="0.1 0.07 0.07"/>
            </geometry>
            <material name="white"/>
        </visual>
        <collision>
            <origin rpy="0 0 0" xyz="0 0 0"/>
            <geometry>
                <box size="0.1 0.07 0.07"/>
            </geometry>
        </collision>
    </link>
    <link name="tablet">
        <inertial>
            <mass value="0.001"/>
            <origin xyz="0 0 0"/>
            <inertia ixx="0.0001" ixy="0.0" ixz="0.0" iyy="0.0001" iyz="0.0" izz="0.0001"/>
        </inertial>
        <visual>
            <origin rpy="0 0 0" xyz="0 0 0"/>
            <geometry>
                <box size="0.006 0.16 0.255"/>
            </geometry>
            <material name="black"/>
        </visual>
        <collision>
            <origin rpy="0 0 0" xyz="0 0 0"/>
            <geometry>
                <box size="0.006 0.16 0.255"/>
            </geometry>
        </collision>
    </link>
    <link name="left_wheel">
        <inertial>
            <mass value="0.001"/>
            <origin xyz="0 0 0"/>
            <inertia ixx="0.0001" ixy="0.0" ixz="0.0" iyy="0.0001" iyz="0.0" izz="0.0001"/>
        </inertial>
        <visual>
            <origin rpy="1.5707 0 0" xyz="0 0 0"/>
            <geometry>
                <cylinder length="0.045" radius="0.07"/>
            </geometry>
            <material name="black"/>
        </visual>
        <collision>
            <origin rpy="1.5707 0 0" xyz="0 0 0"/>
            <geometry>
                <cylinder length="0.045" radius="0.07"/>
            </geometry>
        </collision>
    </link>
    <link name="right_wheel">
        <inertial>
            <mass value="0.001"/>
            <origin xyz="0 0 0"/>
            <inertia ixx="0.0001" ixy="0.0" ixz="0.0" iyy="0.0001" iyz="0.0" izz="0.0001"/>
        </inertial>
        <visual>
            <origin rpy="1.5707 0 0" xyz="0 0 0"/>
            <geometry>
                <cylinder length="0.045" radius="0.07"/>
            </geometry>
            <material name="black"/>
        </visual>
        <collision>
            <origin rpy="1.5707 0 0" xyz="0 0 0"/>
            <geometry>
                <cylinder length="0.045" radius="0.07"/>
            </geometry>
        </collision>
    </link>
    <link name="caster_holder">
        <inertial>
            <mass value="0.001"/>
            <origin xyz="0 0 0"/>
            <inertia ixx="0.0001" ixy="0.0" ixz="0.0" iyy="0.0001" iyz="0.0" izz="0.0001"/>
        </inertial>
        <visual>
            <origin rpy="0 0 0" xyz="0 0 0"/>
            <geometry>
                <box size="0.01 0.015 0.01"/>
            </geometry>
            <material name="grey"/>
        </visual>
        <collision>
            <origin rpy="0 0 0" xyz="0 0 0"/>
            <geometry>
                <box size="0.01 0.015 0.01"/>
            </geometry>
        </collision>
    </link>
    <link name="caster_wheel">
        <inertial>
            <mass value="0.001"/>
            <origin xyz="0 0 0"/>
            <inertia ixx="0.0001" ixy="0.0" ixz="0.0" iyy="0.0001" iyz="0.0" izz="0.0001"/>
        </inertial>
        <visual>
            <origin rpy="1.5707 0 0" xyz="0 0 0"/>
            <geometry>
                <cylinder length="0.02" radius="0.01"/>
            </geometry>
            <material name="black"/>
        </visual>
        <collision>
            <origin rpy="1.5707 0 0" xyz="0 0 0"/>
            <geometry>
                <cylinder length="0.02" radius="0.01"/>
            </geometry>
        </collision>
    </link>
    <link name="raspicam">
      <inertial>
        <origin xyz="0 0 0"/>
        <mass value="0.01" />
        <inertia ixx="0.001" ixy="0.0" ixz="0.0"
          iyy="0.001" iyz="0.0" izz="0.001" />
      </inertial>

      <visual>
        <origin xyz="0 0 0" rpy="0 0 0" />
        <geometry>
          <cylinder radius="0.01" length = "0.005"/>
        </geometry>
        <material name ="Green" />
      </visual>

      <collision>
        <origin xyz="0 0 0" rpy="0 0 0" />
        <geometry>
          <cylinder radius="0.01" length = "0.005"/>
        </geometry>
      </collision>
    </link>
    
    <joint name="footprint_base" type="fixed">
        <origin rpy="0 0 0" xyz="0.085 0 0.085"/>
        <parent link="base_footprint"/>
        <child link="base_link"/>
    </joint> 
    <joint name="base_pole" type="fixed">
        <origin rpy="0 0 0" xyz="0.075 0 0"/>
        <parent link="base_link"/>
        <child link="pole"/>
    </joint>   
    <joint name="tablet_holder_joint" type="revolute">
        <origin rpy="0 0 0" xyz="0 0 0.765"/>
         <limit effort="30" lower="-0.785398" upper="0.05" velocity= "0.5"/>
        <axis xyz="0 1 0" />
        <parent link="pole"/>
        <child link="tablet_holder"/>
    </joint>   
    <joint name="tablet_joint" type="fixed">
        <origin rpy="0 0 0" xyz="0.05 0 0"/>
        <parent link="tablet_holder"/>
        <child link="tablet"/>
    </joint>
    <joint name="leftwheel_joint" type="continuous">
        <origin rpy="0 0 0" xyz="-0.085 0.11 -0.015"/>
        <axis xyz="0 1 0" />
        <parent link="base_link"/>
        <child link="left_wheel"/>
    </joint>
    <joint name="rightwheel_joint" type="continuous">
        <origin rpy="0 0 0" xyz="-0.085 -0.11 -0.015"/>
        <axis xyz="0 1 0" />
        <parent link="base_link"/>
        <child link="right_wheel"/>
    </joint>
    <joint name="casterholder_joint" type="continuous">
        <origin rpy="0 0 0" xyz="0.105 0 -0.07"/>
        <axis xyz="0 0 1" />
        <parent link="base_link"/>
        <child link="caster_holder"/>
    </joint>
    <joint name="caster_joint" type="continuous">
        <origin rpy="0 0 0" xyz="0 0 -0.005"/>
        <axis xyz="0 1 0" />
        <parent link="caster_holder"/>
        <child link="caster_wheel"/>
    </joint>
    <joint name="raspicam_footprint" type="fixed">
      <origin xyz="0.15 0 0.885" rpy="0 0 -1.5708"/>
      <parent link="base_footprint"/>
      <child link="raspicam" />
    </joint>
</robot>

